"use strict";
// Copyright (C) 2017 Ecma International.  All rights reserved.
// This code is governed by the BSD license found in the LICENSE file.
/*---
description: |
    Collection of assertion functions used throughout test262
defines: [assert]
---*/


function assert(mustBeTrue, message) {
  if (mustBeTrue === true) {
    return;
  }

  if (message === undefined) {
    message = 'Expected true but got ' + assert._toString(mustBeTrue);
  }
  throw new Test262Error(message);
}

assert._isSameValue = function (a, b) {
  if (a === b) {
    // Handle +/-0 vs. -/+0
    return a !== 0 || 1 / a === 1 / b;
  }

  // Handle NaN vs. NaN
  return a !== a && b !== b;
};

assert.sameValue = function (actual, expected, message) {
  try {
    if (assert._isSameValue(actual, expected)) {
      return;
    }
  } catch (error) {
    throw new Test262Error(message + ' (_isSameValue operation threw) ' + error);
    return;
  }

  if (message === undefined) {
    message = '';
  } else {
    message += ' ';
  }

  message += 'Expected SameValue(«' + assert._toString(actual) + '», «' + assert._toString(expected) + '») to be true';

  throw new Test262Error(message);
};

assert.notSameValue = function (actual, unexpected, message) {
  if (!assert._isSameValue(actual, unexpected)) {
    return;
  }

  if (message === undefined) {
    message = '';
  } else {
    message += ' ';
  }

  message += 'Expected SameValue(«' + assert._toString(actual) + '», «' + assert._toString(unexpected) + '») to be false';

  throw new Test262Error(message);
};

assert.throws = function (expectedErrorConstructor, func, message) {
  var expectedName, actualName;
  if (typeof func !== "function") {
    throw new Test262Error('assert.throws requires two arguments: the error constructor ' +
      'and a function to run');
    return;
  }
  if (message === undefined) {
    message = '';
  } else {
    message += ' ';
  }

  try {
    func();
  } catch (thrown) {
    if (typeof thrown !== 'object' || thrown === null) {
      message += 'Thrown value was not an object!';
      throw new Test262Error(message);
    } else if (thrown.constructor !== expectedErrorConstructor) {
      expectedName = expectedErrorConstructor.name;
      actualName = thrown.constructor.name;
      if (expectedName === actualName) {
        message += 'Expected a ' + expectedName + ' but got a different error constructor with the same name';
      } else {
        message += 'Expected a ' + expectedName + ' but got a ' + actualName;
      }
      throw new Test262Error(message);
    }
    return;
  }

  message += 'Expected a ' + expectedErrorConstructor.name + ' to be thrown but no exception was thrown at all';
  throw new Test262Error(message);
};

assert._toString = function (value) {
  try {
    if (value === 0 && 1 / value === -Infinity) {
      return '-0';
    }

    return String(value);
  } catch (err) {
    if (err.name === 'TypeError') {
      return Object.prototype.toString.call(value);
    }

    throw err;
  }
};

// Copyright (c) 2012 Ecma International.  All rights reserved.
// This code is governed by the BSD license found in the LICENSE file.
/*---
description: |
    Provides both:

    - An error class to avoid false positives when testing for thrown exceptions
    - A function to explicitly throw an exception using the Test262Error class
defines: [Test262Error, $DONOTEVALUATE]
---*/


function Test262Error(message) {
  this.message = message || "";
}

Test262Error.prototype.toString = function () {
  return "Test262Error: " + this.message;
};

Test262Error.thrower = (message) => {
  throw new Test262Error(message);
};

function $DONOTEVALUATE() {
  throw "Test262: This statement should not be evaluated.";
}

// Copyright 2009 the Sputnik authors.  All rights reserved.
// This code is governed by the BSD license found in the LICENSE file.

/*---
info: Using "try" with "catch" or "finally" statement with a "return" statement
es5id: 12.14_A13_T2
description: Using try/finally syntax construction
---*/

// CHECK#1
var c1=0;
function myFunction1(){
  try{
    return 1;
  }finally{
    c1=1;
  }
  return 2;
}
var x1=myFunction1();
if(x1!==1){
  throw new Test262Error('#1.1: x1===1. Actual: x1==='+x1);
}
if (c1!==1){
  throw new Test262Error('#1.2: "finally" block must be evaluated');
}

// CHECK#2
var c2=0;
function myFunction2(){
  try{
    throw "exc";
    return 1;
  }finally{
    c2=1;
  }
  return 2;
}
try{
  var x2=myFunction2();
  throw new Test262Error('#2.1: Throwing exception inside function lead to throwing exception outside this function');
}
catch(e){
  if (c2!==1){
    throw new Test262Error('#2.2: "finally" block must be evaluated');
  }
}

// CHECK#3
var c3=0;
function myFunction3(){
  try{
    return someValue;
  }finally{
    c3=1;
  }
  return 2;
}
try{
  var x3=myFunction3();
  throw new Test262Error('#3.1: Throwing exception inside function lead to throwing exception outside this function');
}
catch(e){
  if (c3!==1){
    throw new Test262Error('#3.2: "finally" block must be evaluated');
  }
}

// CHECK#4
var c4=0;
function myFunction4(){
  try{
    return 1;
  }finally{
    c4=1;
    throw "exc";
    return 0;
  }
  return 2;
}
try{
  var x4=myFunction4();
  throw new Test262Error('#4.2: Throwing exception inside function lead to throwing exception outside this function');
}
catch(e){
  if (c4!==1){
    throw new Test262Error('#4.3: "finally" block must be evaluated');
  }
}

// CHECK#5
var c5=0;
function myFunction5(){
  try{
    return 1;
  }finally{
    c5=1;
    return someValue;
    return 0;
  }
  return 2;
}
try{
  var x5=myFunction5();
  throw new Test262Error('#5.2: Throwing exception inside function lead to throwing exception outside this function');
}
catch(e){
  if (c5!==1){
    throw new Test262Error('#5.3: "finally" block must be evaluated');
  }
}

// CHECK#6
var c6=0;
function myFunction6(){
  try{
    throw "ex1";
    return 1;
  }finally{
    c6=1;
    throw "ex2";
    return 2;
  }
  return 3;
}
try{
  var x6=myFunction6();
  throw new Test262Error('#6.1: Throwing exception inside function lead to throwing exception outside this function');
}
catch(e){
  if(e==="ex1"){
    throw new Test262Error('#6.2: Exception !=="ex1". Actual: catch previous exception');
  }
  if(e!=="ex2"){
    throw new Test262Error('#6.3: Exception !=="ex1". Actual: '+e);
  }
  if (c6!==1){
    throw new Test262Error('#6.4: "finally" block must be evaluated');
  }
}

// CHECK#7
var c7=0;
function myFunction7(){
  try{
    return 1;
  }finally{
    c7=1;
    return 2;
  }
  return 3;
}
var x7=myFunction7();
if(x7!==2){
  throw new Test262Error('#7.1: "catch" block must be evaluated');
}
if (c7!==1){
  throw new Test262Error('#7.2: "finally" block must be evaluated');
}

// CHECK#8
var c8=0;
function myFunction8(){
  try{
    throw "ex1";
  }finally{
    c8=1;
    return 2;
  }
  return 3;
}
try{
  var x8=myFunction8();
}
catch(ex1){
  c8=10;
}
if (c8!==1){
  throw new Test262Error('#8: "finally" block must be evaluated');
}

